<?xml version="1.0" ?>
<robot name="kuka_kr210_r2700" xmlns:xacro="http://wiki.ros.org/xacro">


  <!--URDF FOR BASE LINK -->
  <link name="dekuka">

      <inertial>
        <origin rpy="0 0 0" xyz="-0.017956 -1.5237E-05 0.00015484"/>
        <mass value="6.3154"/>
        <inertia ixx="0.031746" ixy="1.7673E-07" ixz="-6.6558E-06" iyy="0.016686" iyz="1.4304E-07" izz="0.016723"/>
      </inertial>

      <visual>
        <origin rpy="0 0 0" xyz="0.0 0.0 -0.03"/>
        <geometry>
          <mesh filename="package://kuka_kr210_r2700_extra_description/meshes/visual/dekuka.dae"/>
        </geometry>
        <material name="">
          <color rgba="0.75294 0.75294 0.75294 1"/>
        </material>
      </visual>

      <collision>
        <origin rpy="0 0 0" xyz="0.0 0.0 -0.03"/>
        <geometry>
          <mesh filename="package://kuka_kr210_r2700_extra_description/meshes/collision/dekuka.stl"/>
        </geometry>
      </collision>
  </link>
  <link name="base_link">

    <inertial>
      <origin rpy="0 0 0" xyz="-0.027804 0.00039112 0.14035"/>
      <mass value="1572.9"/>
      <inertia ixx="89.282" ixy="-0.47721" ixz="0.85562" iyy="107.51" iyz="0.0067576" izz="172.02"/>
    </inertial>

    <visual>
      <origin rpy="0 0 0" xyz="0 0 0"/>
      <geometry>
        <mesh filename="package://kuka_kr210_r2700_description/meshes/visual/Base_link.dae"/>
      </geometry>
      <material name="">
        <color rgba="0.75294 0.75294 0.75294 1"/>
      </material>
    </visual>

    <collision>
      <origin rpy="0 0 0" xyz="0 0 0"/>
      <geometry>
        <mesh filename="package://kuka_kr210_r2700_description/meshes/collision/base.STL"/>
      </geometry>
    </collision>
    
  </link>
  <!--URDF ROR LINK 1 -->
  <link name="link_1">

    <inertial>
      <origin rpy="0 0 0" xyz="-0.036811 -0.024697 0.56577"/>
      <mass value="1385.5"/>
      <inertia ixx="90.873" ixy="33.809" ixz="17.159" iyy="147.03" iyz="0.063634" izz="168.19"/>
    </inertial>

    <visual>
      <origin rpy="0 0 0" xyz="0 0 -0.35"/>
      <geometry>
        <mesh filename="package://kuka_kr210_r2700_description/meshes/visual/A1.dae"/>
      </geometry>
      <material name="">
        <color rgba="0.75294 0.75294 0.75294 1"/>
      </material>
    </visual>
    
    <collision>
      <origin rpy="0 0 0" xyz="0 0 -0.35"/>
      <geometry>
        <mesh filename="package://kuka_kr210_r2700_description/meshes/collision/A1.STL"/>
      </geometry>
    </collision>

  </link>
  <!-- URDF FOR LINK 2 -->
  <link name="link_2">

    <inertial>
      <origin rpy="0 0 0" xyz="0.016923 -0.19196 0.44751"/>
      <mass value="958.62"/>
      <inertia ixx="180.42" ixy="-0.83462" ixz="0.32549" iyy="177.68" iyz="-20.82" izz="20.495"/>
    </inertial>

    <visual>
      <origin rpy="0 0 0" xyz="-0.35 0.05 -0.668"/>
      <geometry>
        <mesh filename="package://kuka_kr210_r2700_description/meshes/visual/A2.dae"/>
      </geometry>
      <material name="">
        <color rgba="0.75294 0.75294 0.75294 1"/>
      </material>
    </visual>

    <collision>
      <origin rpy="0 0 0" xyz="-0.35 0.05 -0.668"/>
      <geometry>
        <mesh filename="package://kuka_kr210_r2700_description/meshes/collision/A2.STL"/>
      </geometry>
    </collision>

  </link>
  <!-- URDF FOR LINK 3 -->
  <link name="link_3">
    <inertial>
      <origin rpy="0 0 0" xyz="0.18842 0.18344 -0.042799"/>
      <mass value="710.03"/>
      <inertia ixx="11.887" ixy="-0.12154" ixz="-1.3604" iyy="98.805" iyz="-0.056505" izz="96.251"/>
    </inertial>
    
    <visual>
      <origin rpy="0 0 0" xyz="-0.35 0.2 -1.82"/>
      <geometry>
        <mesh filename="package://kuka_kr210_r2700_description/meshes/visual/A3.dae"/>
      </geometry>
      <material name="">
        <color rgba="0.75294 0.75294 0.75294 1"/>
      </material>
    </visual>

    <collision>
      <origin rpy="0 0 0" xyz="-0.35 0.2 -1.82"/>
      <geometry>
        <mesh filename="package://kuka_kr210_r2700_description/meshes/collision/A3.STL"/>
      </geometry>
    </collision>

  </link>
  <!-- URDF FOR LINK 4 -->
  <link name="link_4">
    <inertial>
      <origin rpy="0 0 0" xyz="0.27146 -0.007326 5.2775E-05"/>
      <mass value="173.73"/>
      <inertia ixx="1.8001" ixy="-0.18515" ixz="0.00051232" iyy="5.514" iyz="0.00070469" izz="6.3498"/>
    </inertial>
    <visual>
      <origin rpy="0 0 0" xyz="-1.109 0.0 -1.79"/>
      <geometry>
        <mesh filename="package://kuka_kr210_r2700_description/meshes/visual/A4.dae"/>
      </geometry>
      <material name="">
        <color rgba="0.75294 0.75294 0.75294 1"/>
      </material>
    </visual>
    <collision>
      <origin rpy="0 0 0" xyz="-1.109 0.0 -1.79"/>
      <geometry>
        <mesh filename="package://kuka_kr210_r2700_description/meshes/collision/A4.STL"/>
      </geometry>
    </collision>
  </link>
  <!-- URDF FOR LINK 5 -->
  <link name="link_5">

    <inertial>
      <origin rpy="0 0 0" xyz="0.04379 0.025984 3.5491E-07"/>
      <mass value="72.17"/>
      <inertia ixx="0.3938" ixy="-0.085332" ixz="1.7223E-06" iyy="0.68945" iyz="-7.0292E-06" izz="0.67292"/>
    </inertial>

    <visual>
      <origin rpy="0 0 0" xyz="-1.547 0.0 -1.78"/>
      <geometry>
        <mesh filename="package://kuka_kr210_r2700_description/meshes/visual/A5.dae"/>
      </geometry>
      <material name="">
        <color rgba="0.75294 0.75294 0.75294 1"/>
      </material>
    </visual>

    <collision>
      <origin rpy="0 0 0" xyz="-1.547 0.0 -1.78"/>
      <geometry>
        <mesh filename="package://kuka_kr210_r2700_description/meshes/collision/A5.STL"/>
      </geometry>
    </collision>

  </link>
  <!-- URDF FOR LINK 6 -->
  <link name="link_6">

    <inertial>
      <origin rpy="0 0 0" xyz="-0.017956 -1.5237E-05 0.00015484"/>
      <mass value="6.3154"/>
      <inertia ixx="0.031746" ixy="1.7673E-07" ixz="-6.6558E-06" iyy="0.016686" iyz="1.4304E-07" izz="0.016723"/>
    </inertial>

    <visual>
      <origin rpy="0 0 0" xyz="-1.747 0.0 -1.78"/>
      <geometry>
        <mesh filename="package://kuka_kr210_r2700_description/meshes/visual/A6.dae"/>
      </geometry>
      <material name="">
        <color rgba="0.75294 0.75294 0.75294 1"/>
      </material>
    </visual>

    <collision>
      <origin rpy="0 0 0" xyz="-1.747 0.0 -1.78"/>
      <geometry>
        <mesh filename="package://kuka_kr210_r2700_description/meshes/collision/A6.STL"/>
      </geometry>
    </collision>
  </link>
  <!-- URDF FOR TOOL  -->
  <link name="tool_link">

    <inertial>
      <origin rpy="0 0 0" xyz="-0.017956 -1.5237E-05 0.00015484"/>
      <mass value="6.3154"/>
      <inertia ixx="0.031746" ixy="1.7673E-07" ixz="-6.6558E-06" iyy="0.016686" iyz="1.4304E-07" izz="0.016723"/>
    </inertial>

    <visual>
      <origin rpy="0 0 0" xyz="-2.0 0.0 -1.42"/>
      <geometry>
        <mesh filename="package://kuka_kr210_r2700_description/meshes/visual/tool.dae"/>
      </geometry>
      <material name="">
        <color rgba="0.75294 0.75294 0.75294 1"/>
      </material>
    </visual>

    <collision>
      <origin rpy="0 0 0" xyz="-2.0 0.0 -1.42"/>
      <geometry>
        <mesh filename="package://kuka_kr210_r2700_description/meshes/collision/SPINDLE.STL"/>
      </geometry>
    </collision>
  </link>
  <!-- SETUP TF for robot -->
   <joint name="de" type="fixed">
    <origin rpy="0 0  0" xyz="0 0 0"/>
    <parent link="dekuka"/>
    <child link="base_link"/>
  </joint>
  <joint name="joint_a1" type="revolute">
    <origin rpy="0 0 0" xyz="-0.00262 0.00097586 0.33099"/>
    <parent link="base_link"/>
    <child link="link_1"/>
    <axis xyz="0 0 1"/>
    <limit effort="0" lower="-3.228859205" upper="3.228859205" velocity="2.146755039"/>
  </joint>

  <joint name="joint_a2" type="revolute">
    <origin rpy="0 0 0" xyz="0.35277 -0.037476 0.3192"/>
    <parent link="link_1"/>
    <child link="link_2"/>
    <axis xyz="0 1 0"/>
    <limit effort="0" lower="-0.785398185" upper="1.483529905" velocity="2.007128695"/>
  </joint>

  <joint name="joint_a3" type="revolute">
    <origin rpy="0 0 0" xyz="0 -0.1475 1.15"/>
    <parent link="link_2"/>
    <child link="link_3"/>
    <axis xyz="0 1 0"/>
    <limit effort="0" lower="-3.66519153" upper="1.134464045" velocity="1.954768816"/>
  </joint>

  <joint name="joint_a4" type="revolute">
    <origin rpy="0 0 0" xyz="0.75795 0.194 -0.041"/>
    <parent link="link_3"/>
    <child link="link_4"/>
    <axis xyz="1 0 0"/>
    <limit effort="0" lower="-6.10865255" upper="6.10865255" velocity="3.124139447"/>
  </joint>

  <joint name="joint_a5" type="revolute">
    <origin rpy="0 0 0" xyz="0.4479 0 0"/>
    <parent link="link_4"/>
    <child link="link_5"/>
    <axis xyz="0 1 0"/>
    <limit effort="0" lower="-2.181661625" upper="2.181661625" velocity="3.001966396"/>
  </joint>
  
  <joint name="joint_a6" type="revolute">
    <origin rpy="0 0 0" xyz="0.1925 0 0"/>
    <parent link="link_5"/>
    <child link="link_6"/>
    <axis xyz="1 0 0"/>
    <limit effort="0" lower="-6.10865255" upper="6.10865255" velocity="3.822271167"/>
  </joint>

  <joint name="tool" type="fixed">
    <origin rpy="0 0 0" xyz="0.20 0 -0.37"/>
    <parent link="link_6"/>
    <child link="tool_link"/>
  </joint>


  
</robot>
